<?xml version='1.0'?>
<sdf version='1.6'>
	<model name='citizen_extras_male_03'>
	<static>false</static>
		<link name="base_link">
		<must_be_base_link>1</must_be_base_link>
		</link>
		<link name="link">
		<pose>0 0 0.1 0 0 1.57</pose>
     <inertial>
       <mass>20</mass>
       <inertia>
         <ixx>0.0</ixx>
         <ixy>0.0</ixy>
         <ixz>0.0</ixz>
         <iyy>0.0</iyy>
         <iyz>0.0</iyz>
         <izz>0.0</izz>
       </inertia>
     </inertial>
     <collision name="collision">
       <pose>0 0 0 0 0 0</pose>
       <geometry>
         <mesh>
           <uri>model://citizen_extras_male_03/meshes/mesh.dae</uri>
         </mesh>
       </geometry>
     </collision>
     <visual name="visual">
       <pose>0 0 0 0 0 0</pose>
       <geometry>
         <mesh>
           <uri>model://citizen_extras_male_03/meshes/mesh.dae</uri>
         </mesh>
       </geometry>
     </visual>
    </link>
			<pose>0.1 0 0 0 0 0</pose>
			<link name='chassis'>
			<inertial>
			</inertial>
			  <pose>0 0 .1 0 0 0</pose>
			  <collision name='collision'>
				<geometry>
				  <box>
				    <size>.4 .2 .1</size>
				  </box>
				</geometry>
			  </collision>

			  

			  <collision name='caster_collision'>
				<pose>-0.15 0 -0.05 0 0 0</pose>
				<geometry>
				  <sphere>
				  <radius>.05</radius>
				</sphere>
			  </geometry>

			  <surface>
				<friction>
				  <ode>
				    <mu>0</mu>
				    <mu2>0</mu2>
				    <slip1>1.0</slip1>
				    <slip2>1.0</slip2>
				  </ode>
				</friction>
			  </surface>
			</collision>

			
		  </link>
		  <link name="left_wheel">
			<pose>0.1 0.13 0.1 0 1.5707 1.5707</pose>
			<collision name="collision">
			  <geometry>
				<cylinder>
				  <radius>.1</radius>
				  <length>.05</length>
				</cylinder>
			  </geometry>
			</collision>
			</link>
			

		  <link name="right_wheel">
			<pose>0.1 -0.13 0.1 0 1.5707 1.5707</pose>
			<collision name="collision">
			  <geometry>
				<cylinder>
				  <radius>.1</radius>
				  <length>.05</length>
				</cylinder>
			  </geometry>
			</collision>
			
		  </link>
		   <joint type="revolute" name="left_wheel_hinge">
		    <pose>0 0 -0.03 0 0 0</pose>
		    <child>left_wheel</child>
		    <parent>chassis</parent>
		    <axis>
		      <xyz>0 0 1</xyz>
		    </axis>
		  </joint>

		  <joint type="revolute" name="right_wheel_hinge">
		    <pose>0 0 0.03 0 0 0</pose>
		    <child>right_wheel</child>
		    <parent>chassis</parent>
		    <axis>
		      <xyz>0 0 1</xyz>
		    </axis>
		  </joint>
		  
		   <joint type="fixed" name="link_chassis">
		    <pose>0 0 0.03 0 0 0</pose>
		    <child>link</child>
		    <parent>chassis</parent>
		    <axis>
		      <xyz>0 0 1</xyz>
		    </axis>
		  </joint>
		  
		  <joint type="fixed" name="base_link">
		    <pose>0 0 0.03 0 0 0</pose>
		    <child>chassis</child>
		    <parent>base_link</parent>
		    <axis>
		      <xyz>0 0 1</xyz>
		    </axis>
		  </joint>
		  
		  	<plugin name="differential_drive_controller" 		
				filename="libgazebo_ros_diff_drive.so">
				<alwaysOn>true</alwaysOn>
				<updateRate>10</updateRate>
				<leftJoint>left_wheel_hinge</leftJoint>
				<rightJoint>right_wheel_hinge</rightJoint>
				<wheelSeparation>0.5</wheelSeparation>
				<wheelDiameter>0.1</wheelDiameter>
				<commandTopic>cmd_vel</commandTopic>
				<odometryTopic>odom</odometryTopic>
				<odometryFrame>odom</odometryFrame>
				<robotBaseFrame>base_footprint</robotBaseFrame>
				<publishWheelJointState>false</publishWheelJointState>
				<robotNamespace></robotNamespace>
				<rosDebugLevel>false</rosDebugLevel>
				<publishWheelTF>false</publishWheelTF>
				<publishOdomTF>false</publishOdomTF>
				<wheelAcceleration>0</wheelAcceleration>
				<wheelTorque>1.41</wheelTorque>
				<odometrySource>world</odometrySource>
				<publishTf>false</publishTf>
                <legacyMode>false</legacyMode>
			</plugin>
	</model>
</sdf>
